<?xml version="1.0"?>
<!-- Kinematics-only B601-RS chain. No Gazebo plugins, meshes or simulation data. -->
<robot name="rebot_b601_kinematics">
  <link name="base_link"/><link name="link1"/><link name="link2"/>
  <link name="link3"/><link name="link4"/><link name="link5"/>
  <link name="link6"/><link name="gripper_end"/>
  <joint name="joint1" type="revolute">
    <origin xyz="-0.00034283 -0.00098683 0.075" rpy="0 0 0"/>
    <parent link="base_link"/><child link="link1"/><axis xyz="0 0 -1"/>
    <limit lower="-2.8" upper="2.8" effort="36" velocity="50"/>
  </joint>
  <joint name="joint2" type="revolute">
    <origin xyz="0.020343 0.027237 0.07" rpy="-1.5708 0 0"/>
    <parent link="link1"/><child link="link2"/><axis xyz="0 0 1"/>
    <limit lower="0" upper="3.14" effort="36" velocity="50"/>
  </joint>
  <joint name="joint3" type="revolute">
    <origin xyz="-0.236 0 0" rpy="0 0 0"/>
    <parent link="link2"/><child link="link3"/><axis xyz="0 0 -1"/>
    <limit lower="-0.01" upper="3.14" effort="36" velocity="50"/>
  </joint>
  <joint name="joint4" type="revolute">
    <origin xyz="0.228 -0.072746 0.0045" rpy="0 0 0"/>
    <parent link="link3"/><child link="link4"/><axis xyz="0 0 -1"/>
    <limit lower="-1.57" upper="1.57" effort="14" velocity="40"/>
  </joint>
  <joint name="joint5" type="revolute">
    <origin xyz="0.087 -0.048 -0.03075" rpy="-1.5708 0 0"/>
    <parent link="link4"/><child link="link5"/><axis xyz="0 0 -1"/>
    <limit lower="-1.57" upper="1.57" effort="14" velocity="40"/>
  </joint>
  <joint name="joint6" type="revolute">
    <origin xyz="0.0365 0 0.048" rpy="0 1.5708 0"/>
    <parent link="link5"/><child link="link6"/><axis xyz="0 0 -1"/>
    <limit lower="-3.14" upper="3.14" effort="14" velocity="40"/>
  </joint>
  <joint name="tool_fixed" type="fixed">
    <origin xyz="0 0 0.16621" rpy="3.1416 -1.5708 0"/>
    <parent link="link6"/><child link="gripper_end"/>
  </joint>
</robot>
